Workbook

Sheet 入力仕様
A1: 項目 | B1: 入力規則 | C1: 仕様備考等 | D1: 入力ヒント（赤字）
A2: ID | B2: 半角英数 | C2: 数字10桁
A3: 登録情報 | B3: 半角英数 | D3: 変更なし=1 変更あり=2
A4: 郵便番号 | B4: 半角英数 | D4: ハイフンなし7桁
A5: 都道府県 | B5: 全角 | C5: 郵便番号を入力した場合、自動検索 フォーカス移動時、英数記号を半角化
A6: 市区町村 | B6: 全角 | C6: 郵便番号を入力した場合、自動検索 フォーカス移動時、英数記号を半角化
A7: 町域番地 | B7: 全角 | C7: 郵便番号を入力した場合、自動検索 フォーカス移動時、英数記号を半角化
A8: 建物 | B8: 全角 | C8: フォーカス移動時、英数記号を半角化
A9: 氏名かな | B9: 全角 | D9: ひらがな スペースあり | E9: 2025/5/12修正
A10: 氏名 | B10: 全角 | D10: スペースあり | E10: 2025/5/12修正
A11: 電話番号 | B11: 半角英数 | C11: 数字10桁～11桁 | D11: ハイフンなし
A12: 防災カルタ | B12: 半角英数 | D12: 申し込む=1 不要=2
A13: 404:薬剤式トイレ | B13: 半角英数 | D13: 数量を入力（薬剤式トイレ） | E13: 2025/5/12修正
A14: 225:備蓄ランタン | B14: 半角英数 | D14: 数量を入力（備蓄ランタン） | E14: 2025/5/12修正
A15: 512:彩り主食 | B15: 半角英数 | D15: 数量を入力（彩り主食） | E15: 2025/5/12修正
A16: 411&415:全身きれい | B16: 半角英数 | D16: 数量を入力（全身きれい・歯みがき） | E16: 2025/5/12修正
A17: 画像名 | C17: 画像名を自動記録（PDF）

Sheet 変換前のテーブル
A1: index | B1: display_name | C1: data_type | D1: label_name | E1: line_edit_name | F1: is_last | G1: line_edit_obj | H1: ime_mode | I1: pn_auto_input | J1: text_conversion | K1: label_obj | L1: frame_a_obj | M1: frame_a_name | N1: frame_b_obj | O1: frame_b_name | P1: layout_a_name | Q1: layout_a_obj | R1: layout_b_name | S1: layout_b_obj | T1: info | U1: is_rept | V1: is_show | W1: list_item | X1: name | Y1: replace_keys | Z1: replace_values | AA1: is_b_line_show | AB1: length | AC1: min_max | AD1: re | AE1: remarks | BK1: index | BL1: list | BM1: conv | BN1: min | BO1: max | BP1: inli_text | BQ1: list2 | BR1: list2_ | BS1: min_ | BT1: max_ | BU1: min_max
A2: =ROW()-2 -> 0 | B2: =SUBSTITUTE(変換前のテーブル[[#This Row],[name]],"：",":")&":" -> ID: | C2: hankaku-eisu-kuromaru_lenjust | D2: ="label_"&変換前のテーブル[[#This Row],[index]]&"_" -> label_0_ | E2: ="lineEdit_"&変換前のテーブル[[#This Row],[index]]&"_" -> lineEdit_0_ | F2: {=_xlfn.IFS(ROW()-1=1,-1,ROW()-1=ROWS(変換前のテーブル[index]),1,TRUE,0)} -> -1 | H2: en | I2: null | M2: ="frame_"&INT((ROW()-2) / 3)&"_" -> frame_0_ | O2: ="frame__"&変換前のテーブル[[#This Row],[index]]&"__" -> frame__0__ | P2: ="horizontalLayout_"&INT((ROW()-2) / 3)&"_" -> horizontalLayout_0_ | R2: ="horizontalLayout__"&変換前のテーブル[[#This Row],[index]]&"__" -> horizontalLayout__0__ | T2: ID: 数字10桁 | U2: False | V2: True | X2: ID | AB2: 10 | BK2: 0 | BL2: =変換前のテーブル[[#This Row],[list_item]] & "" | BM2: =SUBSTITUTE(SUBSTITUTE(SUBSTITUTE(_参照テーブル[[#This Row],[list]], "'", ""),"[", ""), "]", "") | BN2: {=MIN(VALUE(_xlfn.TEXTSPLIT(_参照テーブル[[#This Row],[conv]], ", ")))} -> #VALUE! | BO2: {=MAX(VALUE(_xlfn.TEXTSPLIT(_参照テーブル[[#This Row],[conv]], ", ")))} -> #VALUE! | BP2: =IFERROR("("&_参照テーブル[[#This Row],[min]]&"～"&_参照テーブル[[#This Row],[max]]&")","") | BQ2: =変換前のテーブル[[#This Row],[min_max]] -> 0 | BR2: =SUBSTITUTE(SUBSTITUTE(_参照テーブル[[#This Row],[list2]],"[",""),"]","") -> 0 | BS2: {=_xlfn.CHOOSECOLS(_xlfn.TEXTSPLIT(_参照テーブル[[#This Row],[list2_]],","),1)} -> 0 | BT2: {=_xlfn.CHOOSECOLS(_xlfn.TEXTSPLIT(_参照テーブル[[#This Row],[list2_]],","),2)} -> #VALUE! | BU2: =IFERROR("("&_参照テーブル[[#This Row],[min_]]&"～"&_参照テーブル[[#This Row],[max_]]&")", "")
A3: =ROW()-2 -> 1 | B3: =SUBSTITUTE(変換前のテーブル[[#This Row],[name]],"：",":")&":" -> 登録情報: | C3: hankaku-eisu-kuromaru | D3: ="label_"&変換前のテーブル[[#This Row],[index]]&"_" -> label_1_ | E3: ="lineEdit_"&変換前のテーブル[[#This Row],[index]]&"_" -> lineEdit_1_ | F3: {=_xlfn.IFS(ROW()-1=1,-1,ROW()-1=ROWS(変換前のテーブル[index]),1,TRUE,0)} -> 0 | H3: en | I3: null | M3: ="frame_"&INT((ROW()-2) / 3)&"_" -> frame_0_ | O3: ="frame__"&変換前のテーブル[[#This Row],[index]]&"__" -> frame__1__ | P3: ="horizontalLayout_"&INT((ROW()-2) / 3)&"_" -> horizontalLayout_0_ | R3: ="horizontalLayout__"&変換前のテーブル[[#This Row],[index]]&"__" -> horizontalLayout__1__ | T3: 登録情報: 変更なし=1 変更あり=2 | U3: False | V3: True | X3: 登録情報 | BK3: =BK2+1 -> 1 | BL3: =変換前のテーブル[[#This Row],[list_item]] & "" | BM3: =SUBSTITUTE(SUBSTITUTE(SUBSTITUTE(_参照テーブル[[#This Row],[list]], "'", ""),"[", ""), "]", "") | BN3: {=MIN(VALUE(_xlfn.TEXTSPLIT(_参照テーブル[[#This Row],[conv]], ", ")))} -> #VALUE! | BO3: {=MAX(VALUE(_xlfn.TEXTSPLIT(_参照テーブル[[#This Row],[conv]], ", ")))} -> #VALUE! | BP3: =IFERROR("("&_参照テーブル[[#This Row],[min]]&"～"&_参照テーブル[[#This Row],[max]]&")","") | BQ3: =変換前のテーブル[[#This Row],[min_max]] -> 0 | BR3: =SUBSTITUTE(SUBSTITUTE(_参照テーブル[[#This Row],[list2]],"[",""),"]","") -> 0 | BS3: {=_xlfn.CHOOSECOLS(_xlfn.TEXTSPLIT(_参照テーブル[[#This Row],[list2_]],","),1)} -> 0 | BT3: {=_xlfn.CHOOSECOLS(_xlfn.TEXTSPLIT(_参照テーブル[[#This Row],[list2_]],","),2)} -> #VALUE! | BU3: =IFERROR("("&_参照テーブル[[#This Row],[min_]]&"～"&_参照テーブル[[#This Row],[max_]]&")", "")
A4: =ROW()-2 -> 2 | B4: =SUBSTITUTE(変換前のテーブル[[#This Row],[name]],"：",":")&":" -> 郵便番号: | C4: hankaku-eisu-kuromaru | D4: ="label_"&変換前のテーブル[[#This Row],[index]]&"_" -> label_2_ | E4: ="lineEdit_"&変換前のテーブル[[#This Row],[index]]&"_" -> lineEdit_2_ | F4: {=_xlfn.IFS(ROW()-1=1,-1,ROW()-1=ROWS(変換前のテーブル[index]),1,TRUE,0)} -> 0 | H4: en | I4: postnum | J4: han | M4: ="frame_"&INT((ROW()-2) / 3)&"_" -> frame_0_ | O4: ="frame__"&変換前のテーブル[[#This Row],[index]]&"__" -> frame__2__ | P4: horizontalLayout_1_ | R4: ="horizontalLayout__"&変換前のテーブル[[#This Row],[index]]&"__" -> horizontalLayout__2__ | T4: 郵便番号: ハイフンなし7桁 | U4: False | V4: True | X4: 郵便番号 | AA4: True | BK4: =BK3+1 -> 2 | BL4: =変換前のテーブル[[#This Row],[list_item]] & "" | BM4: =SUBSTITUTE(SUBSTITUTE(SUBSTITUTE(_参照テーブル[[#This Row],[list]], "'", ""),"[", ""), "]", "") | BN4: {=MIN(VALUE(_xlfn.TEXTSPLIT(_参照テーブル[[#This Row],[conv]], ", ")))} -> #VALUE! | BO4: {=MAX(VALUE(_xlfn.TEXTSPLIT(_参照テーブル[[#This Row],[conv]], ", ")))} -> #VALUE! | BP4: =IFERROR("("&_参照テーブル[[#This Row],[min]]&"～"&_参照テーブル[[#This Row],[max]]&")","") | BQ4: =変換前のテーブル[[#This Row],[min_max]] -> 0 | BR4: =SUBSTITUTE(SUBSTITUTE(_参照テーブル[[#This Row],[list2]],"[",""),"]","") -> 0 | BS4: {=_xlfn.CHOOSECOLS(_xlfn.TEXTSPLIT(_参照テーブル[[#This Row],[list2_]],","),1)} -> 0 | BT4: {=_xlfn.CHOOSECOLS(_xlfn.TEXTSPLIT(_参照テーブル[[#This Row],[list2_]],","),2)} -> #VALUE! | BU4: =IFERROR("("&_参照テーブル[[#This Row],[min_]]&"～"&_参照テーブル[[#This Row],[max_]]&")", "")
A5: =ROW()-2 -> 3 | B5: =SUBSTITUTE(変換前のテーブル[[#This Row],[name]],"：",":")&":" -> 都道府県: | C5: str | D5: ="label_"&変換前のテーブル[[#This Row],[index]]&"_" -> label_3_ | E5: ="lineEdit_"&変換前のテーブル[[#This Row],[index]]&"_" -> lineEdit_3_ | F5: {=_xlfn.IFS(ROW()-1=1,-1,ROW()-1=ROWS(変換前のテーブル[index]),1,TRUE,0)} -> 0 | H5: jp | I5: pref | J5: han-ans | M5: ="frame_"&INT((ROW()-2) / 3)&"_" -> frame_1_ | O5: ="frame__"&変換前のテーブル[[#This Row],[index]]&"__" -> frame__3__ | P5: ="horizontalLayout_"&INT((ROW()-2) / 3)&"_" -> horizontalLayout_1_ | R5: ="horizontalLayout__"&変換前のテーブル[[#This Row],[index]]&"__" -> horizontalLayout__3__ | T5: =_xlfn.LET( _xlpm._maxlentext, IF(変換前のテーブル[[#This Row],[length]]="", "", " (桁数:" & SUBSTITUTE(SUBSTITUTE(変換前のテーブル[[#This Row],[length]],"[",""),"]","") & ")"), _xlpm._result, 変換前のテーブル[[#This Row],[name]]&": "&_xlfn.XLOOKUP(変換前のテーブル[[#This Row],[data_type]],_TypeInfo[type],_TypeInfo[info], "") & _参照テーブル[[#This Row],[inli_text]] & _xlpm._maxlentext & _参照テーブル[[#This Row],[min_max]], _xlpm._result ) -> 都道府県: | U5: False | V5: True | X5: 都道府県 | BK5: =BK4+1 -> 3 | BL5: =変換前のテーブル[[#This Row],[list_item]] & "" | BM5: =SUBSTITUTE(SUBSTITUTE(SUBSTITUTE(_参照テーブル[[#This Row],[list]], "'", ""),"[", ""), "]", "") | BN5: {=MIN(VALUE(_xlfn.TEXTSPLIT(_参照テーブル[[#This Row],[conv]], ", ")))} -> #VALUE! | BO5: {=MAX(VALUE(_xlfn.TEXTSPLIT(_参照テーブル[[#This Row],[conv]], ", ")))} -> #VALUE! | BP5: =IFERROR("("&_参照テーブル[[#This Row],[min]]&"～"&_参照テーブル[[#This Row],[max]]&")","") | BQ5: =変換前のテーブル[[#This Row],[min_max]] -> 0 | BR5: =SUBSTITUTE(SUBSTITUTE(_参照テーブル[[#This Row],[list2]],"[",""),"]","") -> 0 | BS5: {=_xlfn.CHOOSECOLS(_xlfn.TEXTSPLIT(_参照テーブル[[#This Row],[list2_]],","),1)} -> 0 | BT5: {=_xlfn.CHOOSECOLS(_xlfn.TEXTSPLIT(_参照テーブル[[#This Row],[list2_]],","),2)} -> #VALUE! | BU5: =IFERROR("("&_参照テーブル[[#This Row],[min_]]&"～"&_参照テーブル[[#This Row],[max_]]&")", "")
A6: =ROW()-2 -> 4 | B6: =SUBSTITUTE(変換前のテーブル[[#This Row],[name]],"：",":")&":" -> 市区町村: | C6: str | D6: ="label_"&変換前のテーブル[[#This Row],[index]]&"_" -> label_4_ | E6: ="lineEdit_"&変換前のテーブル[[#This Row],[index]]&"_" -> lineEdit_4_ | F6: {=_xlfn.IFS(ROW()-1=1,-1,ROW()-1=ROWS(変換前のテーブル[index]),1,TRUE,0)} -> 0 | H6: jp | I6: city | J6: han-ans | M6: ="frame_"&INT((ROW()-2) / 3)&"_" -> frame_1_ | O6: ="frame__"&変換前のテーブル[[#This Row],[index]]&"__" -> frame__4__ | P6: horizontalLayout_1_ | R6: ="horizontalLayout__"&変換前のテーブル[[#This Row],[index]]&"__" -> horizontalLayout__4__ | T6: =_xlfn.LET( _xlpm._maxlentext, IF(変換前のテーブル[[#This Row],[length]]="", "", " (桁数:" & SUBSTITUTE(SUBSTITUTE(変換前のテーブル[[#This Row],[length]],"[",""),"]","") & ")"), _xlpm._result, 変換前のテーブル[[#This Row],[name]]&": "&_xlfn.XLOOKUP(変換前のテーブル[[#This Row],[data_type]],_TypeInfo[type],_TypeInfo[info], "") & _参照テーブル[[#This Row],[inli_text]] & _xlpm._maxlentext & _参照テーブル[[#This Row],[min_max]], _xlpm._result ) -> 市区町村: | U6: False | V6: True | X6: 市区町村 | BK6: =BK5+1 -> 4 | BL6: =変換前のテーブル[[#This Row],[list_item]] & "" | BM6: =SUBSTITUTE(SUBSTITUTE(SUBSTITUTE(_参照テーブル[[#This Row],[list]], "'", ""),"[", ""), "]", "") | BN6: {=MIN(VALUE(_xlfn.TEXTSPLIT(_参照テーブル[[#This Row],[conv]], ", ")))} -> #VALUE! | BO6: {=MAX(VALUE(_xlfn.TEXTSPLIT(_参照テーブル[[#This Row],[conv]], ", ")))} -> #VALUE! | BP6: =IFERROR("("&_参照テーブル[[#This Row],[min]]&"～"&_参照テーブル[[#This Row],[max]]&")","") | BQ6: =変換前のテーブル[[#This Row],[min_max]] -> 0 | BR6: =SUBSTITUTE(SUBSTITUTE(_参照テーブル[[#This Row],[list2]],"[",""),"]","") -> 0 | BS6: {=_xlfn.CHOOSECOLS(_xlfn.TEXTSPLIT(_参照テーブル[[#This Row],[list2_]],","),1)} -> 0 | BT6: {=_xlfn.CHOOSECOLS(_xlfn.TEXTSPLIT(_参照テーブル[[#This Row],[list2_]],","),2)} -> #VALUE! | BU6: =IFERROR("("&_参照テーブル[[#This Row],[min_]]&"～"&_参照テーブル[[#This Row],[max_]]&")", "")
A7: =ROW()-2 -> 5 | B7: =SUBSTITUTE(変換前のテーブル[[#This Row],[name]],"：",":")&":" -> 町域番地: | C7: str | D7: ="label_"&変換前のテーブル[[#This Row],[index]]&"_" -> label_5_ | E7: ="lineEdit_"&変換前のテーブル[[#This Row],[index]]&"_" -> lineEdit_5_ | F7: {=_xlfn.IFS(ROW()-1=1,-1,ROW()-1=ROWS(変換前のテーブル[index]),1,TRUE,0)} -> 0 | H7: jp | I7: town | J7: han-ans | M7: ="frame_"&INT((ROW()-2) / 3)&"_" -> frame_1_ | O7: ="frame__"&変換前のテーブル[[#This Row],[index]]&"__" -> frame__5__ | P7: horizontalLayout_2_ | R7: ="horizontalLayout__"&変換前のテーブル[[#This Row],[index]]&"__" -> horizontalLayout__5__ | T7: =_xlfn.LET( _xlpm._maxlentext, IF(変換前のテーブル[[#This Row],[length]]="", "", " (桁数:" & SUBSTITUTE(SUBSTITUTE(変換前のテーブル[[#This Row],[length]],"[",""),"]","") & ")"), _xlpm._result, 変換前のテーブル[[#This Row],[name]]&": "&_xlfn.XLOOKUP(変換前のテーブル[[#This Row],[data_type]],_TypeInfo[type],_TypeInfo[info], "") & _参照テーブル[[#This Row],[inli_text]] & _xlpm._maxlentext & _参照テーブル[[#This Row],[min_max]], _xlpm._result ) -> 町域番地: | U7: False | V7: True | X7: 町域番地 | BK7: =BK6+1 -> 5 | BL7: =変換前のテーブル[[#This Row],[list_item]] & "" | BM7: =SUBSTITUTE(SUBSTITUTE(SUBSTITUTE(_参照テーブル[[#This Row],[list]], "'", ""),"[", ""), "]", "") | BN7: {=MIN(VALUE(_xlfn.TEXTSPLIT(_参照テーブル[[#This Row],[conv]], ", ")))} -> #VALUE! | BO7: {=MAX(VALUE(_xlfn.TEXTSPLIT(_参照テーブル[[#This Row],[conv]], ", ")))} -> #VALUE! | BP7: =IFERROR("("&_参照テーブル[[#This Row],[min]]&"～"&_参照テーブル[[#This Row],[max]]&")","") | BQ7: =変換前のテーブル[[#This Row],[min_max]] -> 0 | BR7: =SUBSTITUTE(SUBSTITUTE(_参照テーブル[[#This Row],[list2]],"[",""),"]","") -> 0 | BS7: {=_xlfn.CHOOSECOLS(_xlfn.TEXTSPLIT(_参照テーブル[[#This Row],[list2_]],","),1)} -> 0 | BT7: {=_xlfn.CHOOSECOLS(_xlfn.TEXTSPLIT(_参照テーブル[[#This Row],[list2_]],","),2)} -> #VALUE! | BU7: =IFERROR("("&_参照テーブル[[#This Row],[min_]]&"～"&_参照テーブル[[#This Row],[max_]]&")", "")
A8: =ROW()-2 -> 6 | B8: =SUBSTITUTE(変換前のテーブル[[#This Row],[name]],"：",":")&":" -> 建物: | C8: str | D8: ="label_"&変換前のテーブル[[#This Row],[index]]&"_" -> label_6_ | E8: ="lineEdit_"&変換前のテーブル[[#This Row],[index]]&"_" -> lineEdit_6_ | F8: {=_xlfn.IFS(ROW()-1=1,-1,ROW()-1=ROWS(変換前のテーブル[index]),1,TRUE,0)} -> 0 | H8: jp | I8: null | J8: han-ans | M8: ="frame_"&INT((ROW()-2) / 3)&"_" -> frame_2_ | O8: ="frame__"&変換前のテーブル[[#This Row],[index]]&"__" -> frame__6__ | P8: ="horizontalLayout_"&INT((ROW()-2) / 3)&"_" -> horizontalLayout_2_ | R8: ="horizontalLayout__"&変換前のテーブル[[#This Row],[index]]&"__" -> horizontalLayout__6__ | T8: =_xlfn.LET( _xlpm._maxlentext, IF(変換前のテーブル[[#This Row],[length]]="", "", " (桁数:" & SUBSTITUTE(SUBSTITUTE(変換前のテーブル[[#This Row],[length]],"[",""),"]","") & ")"), _xlpm._result, 変換前のテーブル[[#This Row],[name]]&": "&_xlfn.XLOOKUP(変換前のテーブル[[#This Row],[data_type]],_TypeInfo[type],_TypeInfo[info], "") & _参照テーブル[[#This Row],[inli_text]] & _xlpm._maxlentext & _参照テーブル[[#This Row],[min_max]], _xlpm._result ) -> 建物: | U8: False | V8: True | X8: 建物 | BK8: =BK7+1 -> 6 | BL8: =変換前のテーブル[[#This Row],[list_item]] & "" | BM8: =SUBSTITUTE(SUBSTITUTE(SUBSTITUTE(_参照テーブル[[#This Row],[list]], "'", ""),"[", ""), "]", "") | BN8: {=MIN(VALUE(_xlfn.TEXTSPLIT(_参照テーブル[[#This Row],[conv]], ", ")))} -> #VALUE! | BO8: {=MAX(VALUE(_xlfn.TEXTSPLIT(_参照テーブル[[#This Row],[conv]], ", ")))} -> #VALUE! | BP8: =IFERROR("("&_参照テーブル[[#This Row],[min]]&"～"&_参照テーブル[[#This Row],[max]]&")","") | BQ8: =変換前のテーブル[[#This Row],[min_max]] -> 0 | BR8: =SUBSTITUTE(SUBSTITUTE(_参照テーブル[[#This Row],[list2]],"[",""),"]","") -> 0 | BS8: {=_xlfn.CHOOSECOLS(_xlfn.TEXTSPLIT(_参照テーブル[[#This Row],[list2_]],","),1)} -> 0 | BT8: {=_xlfn.CHOOSECOLS(_xlfn.TEXTSPLIT(_参照テーブル[[#This Row],[list2_]],","),2)} -> #VALUE! | BU8: =IFERROR("("&_参照テーブル[[#This Row],[min_]]&"～"&_参照テーブル[[#This Row],[max_]]&")", "")
A9: =ROW()-2 -> 7 | B9: =SUBSTITUTE(変換前のテーブル[[#This Row],[name]],"：",":")&":" -> 氏名かな: | C9: str | D9: ="label_"&変換前のテーブル[[#This Row],[index]]&"_" -> label_7_ | E9: ="lineEdit_"&変換前のテーブル[[#This Row],[index]]&"_" -> lineEdit_7_ | F9: {=_xlfn.IFS(ROW()-1=1,-1,ROW()-1=ROWS(変換前のテーブル[index]),1,TRUE,0)} -> 0 | H9: jp | I9: null | M9: ="frame_"&INT((ROW()-2) / 3)&"_" -> frame_2_ | O9: ="frame__"&変換前のテーブル[[#This Row],[index]]&"__" -> frame__7__ | P9: horizontalLayout_3_ | R9: ="horizontalLayout__"&変換前のテーブル[[#This Row],[index]]&"__" -> horizontalLayout__7__ | T9: 氏名かな: ひらがな スペースあり | U9: False | V9: True | X9: 氏名かな | AA9: True | BK9: =BK8+1 -> 7 | BL9: =変換前のテーブル[[#This Row],[list_item]] & "" | BM9: =SUBSTITUTE(SUBSTITUTE(SUBSTITUTE(_参照テーブル[[#This Row],[list]], "'", ""),"[", ""), "]", "") | BN9: {=MIN(VALUE(_xlfn.TEXTSPLIT(_参照テーブル[[#This Row],[conv]], ", ")))} -> #VALUE! | BO9: {=MAX(VALUE(_xlfn.TEXTSPLIT(_参照テーブル[[#This Row],[conv]], ", ")))} -> #VALUE! | BP9: =IFERROR("("&_参照テーブル[[#This Row],[min]]&"～"&_参照テーブル[[#This Row],[max]]&")","") | BQ9: =変換前のテーブル[[#This Row],[min_max]] -> 0 | BR9: =SUBSTITUTE(SUBSTITUTE(_参照テーブル[[#This Row],[list2]],"[",""),"]","") -> 0 | BS9: {=_xlfn.CHOOSECOLS(_xlfn.TEXTSPLIT(_参照テーブル[[#This Row],[list2_]],","),1)} -> 0 | BT9: {=_xlfn.CHOOSECOLS(_xlfn.TEXTSPLIT(_参照テーブル[[#This Row],[list2_]],","),2)} -> #VALUE! | BU9: =IFERROR("("&_参照テーブル[[#This Row],[min_]]&"～"&_参照テーブル[[#This Row],[max_]]&")", "")
A10: =ROW()-2 -> 8 | B10: =SUBSTITUTE(変換前のテーブル[[#This Row],[name]],"：",":")&":" -> 氏名: | C10: str | D10: ="label_"&変換前のテーブル[[#This Row],[index]]&"_" -> label_8_ | E10: ="lineEdit_"&変換前のテーブル[[#This Row],[index]]&"_" -> lineEdit_8_ | F10: {=_xlfn.IFS(ROW()-1=1,-1,ROW()-1=ROWS(変換前のテーブル[index]),1,TRUE,0)} -> 0 | H10: jp | I10: null | M10: ="frame_"&INT((ROW()-2) / 3)&"_" -> frame_2_ | O10: ="frame__"&変換前のテーブル[[#This Row],[index]]&"__" -> frame__8__ | P10: horizontalLayout_3_ | R10: ="horizontalLayout__"&変換前のテーブル[[#This Row],[index]]&"__" -> horizontalLayout__8__ | T10: 氏名: スペースあり | U10: False | V10: True | X10: 氏名 | BK10: =BK9+1 -> 8 | BL10: =変換前のテーブル[[#This Row],[list_item]] & "" | BM10: =SUBSTITUTE(SUBSTITUTE(SUBSTITUTE(_参照テーブル[[#This Row],[list]], "'", ""),"[", ""), "]", "") | BN10: {=MIN(VALUE(_xlfn.TEXTSPLIT(_参照テーブル[[#This Row],[conv]], ", ")))} -> #VALUE! | BO10: {=MAX(VALUE(_xlfn.TEXTSPLIT(_参照テーブル[[#This Row],[conv]], ", ")))} -> #VALUE! | BP10: =IFERROR("("&_参照テーブル[[#This Row],[min]]&"～"&_参照テーブル[[#This Row],[max]]&")","") | BQ10: =変換前のテーブル[[#This Row],[min_max]] -> 0 | BR10: =SUBSTITUTE(SUBSTITUTE(_参照テーブル[[#This Row],[list2]],"[",""),"]","") -> 0 | BS10: {=_xlfn.CHOOSECOLS(_xlfn.TEXTSPLIT(_参照テーブル[[#This Row],[list2_]],","),1)} -> 0 | BT10: {=_xlfn.CHOOSECOLS(_xlfn.TEXTSPLIT(_参照テーブル[[#This Row],[list2_]],","),2)} -> #VALUE! | BU10: =IFERROR("("&_参照テーブル[[#This Row],[min_]]&"～"&_参照テーブル[[#This Row],[max_]]&")", "")
A11: =ROW()-2 -> 9 | B11: =SUBSTITUTE(変換前のテーブル[[#This Row],[name]],"：",":")&":" -> 電話番号: | C11: hankaku-eisu-kuromaru_lenrange | D11: ="label_"&変換前のテーブル[[#This Row],[index]]&"_" -> label_9_ | E11: ="lineEdit_"&変換前のテーブル[[#This Row],[index]]&"_" -> lineEdit_9_ | F11: {=_xlfn.IFS(ROW()-1=1,-1,ROW()-1=ROWS(変換前のテーブル[index]),1,TRUE,0)} -> 0 | H11: en | I11: null | J11: han | M11: ="frame_"&INT((ROW()-2) / 3)&"_" -> frame_3_ | O11: ="frame__"&変換前のテーブル[[#This Row],[index]]&"__" -> frame__9__ | P11: horizontalLayout_3_ | R11: ="horizontalLayout__"&変換前のテーブル[[#This Row],[index]]&"__" -> horizontalLayout__9__ | T11: 電話番号: ハイフンなし 桁数:10～11 | U11: False | V11: True | X11: 電話番号 | AA11: True | AB11: [10, 11] | BK11: =BK10+1 -> 9 | BL11: =変換前のテーブル[[#This Row],[list_item]] & "" | BM11: =SUBSTITUTE(SUBSTITUTE(SUBSTITUTE(_参照テーブル[[#This Row],[list]], "'", ""),"[", ""), "]", "") | BN11: {=MIN(VALUE(_xlfn.TEXTSPLIT(_参照テーブル[[#This Row],[conv]], ", ")))} -> #VALUE! | BO11: {=MAX(VALUE(_xlfn.TEXTSPLIT(_参照テーブル[[#This Row],[conv]], ", ")))} -> #VALUE! | BP11: =IFERROR("("&_参照テーブル[[#This Row],[min]]&"～"&_参照テーブル[[#This Row],[max]]&")","") | BQ11: =変換前のテーブル[[#This Row],[min_max]] -> 0 | BR11: =SUBSTITUTE(SUBSTITUTE(_参照テーブル[[#This Row],[list2]],"[",""),"]","") -> 0 | BS11: {=_xlfn.CHOOSECOLS(_xlfn.TEXTSPLIT(_参照テーブル[[#This Row],[list2_]],","),1)} -> 0 | BT11: {=_xlfn.CHOOSECOLS(_xlfn.TEXTSPLIT(_参照テーブル[[#This Row],[list2_]],","),2)} -> #VALUE! | BU11: =IFERROR("("&_参照テーブル[[#This Row],[min_]]&"～"&_参照テーブル[[#This Row],[max_]]&")", "")
A12: =ROW()-2 -> 10 | B12: =SUBSTITUTE(変換前のテーブル[[#This Row],[name]],"：",":")&":" -> 防災カルタ: | C12: hankaku-eisu-kuromaru | D12: ="label_"&変換前のテーブル[[#This Row],[index]]&"_" -> label_10_ | E12: ="lineEdit_"&変換前のテーブル[[#This Row],[index]]&"_" -> lineEdit_10_ | F12: {=_xlfn.IFS(ROW()-1=1,-1,ROW()-1=ROWS(変換前のテーブル[index]),1,TRUE,0)} -> 0 | H12: en | I12: null | J12: han | M12: ="frame_"&INT((ROW()-2) / 3)&"_" -> frame_3_ | O12: ="frame__"&変換前のテーブル[[#This Row],[index]]&"__" -> frame__10__ | P12: horizontalLayout_3_ | R12: ="horizontalLayout__"&変換前のテーブル[[#This Row],[index]]&"__" -> horizontalLayout__10__ | T12: 防災カルタ: 申し込む=1 不要=2 | U12: False | V12: True | X12: 防災カルタ | BK12: =BK11+1 -> 10 | BL12: =変換前のテーブル[[#This Row],[list_item]] & "" | BM12: =SUBSTITUTE(SUBSTITUTE(SUBSTITUTE(_参照テーブル[[#This Row],[list]], "'", ""),"[", ""), "]", "") | BN12: {=MIN(VALUE(_xlfn.TEXTSPLIT(_参照テーブル[[#This Row],[conv]], ", ")))} -> #VALUE! | BO12: {=MAX(VALUE(_xlfn.TEXTSPLIT(_参照テーブル[[#This Row],[conv]], ", ")))} -> #VALUE! | BP12: =IFERROR("("&_参照テーブル[[#This Row],[min]]&"～"&_参照テーブル[[#This Row],[max]]&")","") | BQ12: =変換前のテーブル[[#This Row],[min_max]] -> 0 | BR12: =SUBSTITUTE(SUBSTITUTE(_参照テーブル[[#This Row],[list2]],"[",""),"]","") -> 0 | BS12: {=_xlfn.CHOOSECOLS(_xlfn.TEXTSPLIT(_参照テーブル[[#This Row],[list2_]],","),1)} -> 0 | BT12: {=_xlfn.CHOOSECOLS(_xlfn.TEXTSPLIT(_参照テーブル[[#This Row],[list2_]],","),2)} -> #VALUE! | BU12: =IFERROR("("&_参照テーブル[[#This Row],[min_]]&"～"&_参照テーブル[[#This Row],[max_]]&")", "")
A13: =ROW()-2 -> 11 | B13: =SUBSTITUTE(変換前のテーブル[[#This Row],[name]],"：",":")&":" -> 404:薬剤式トイレ: | C13: hankaku-eisu-kuromaru | D13: ="label_"&変換前のテーブル[[#This Row],[index]]&"_" -> label_11_ | E13: ="lineEdit_"&変換前のテーブル[[#This Row],[index]]&"_" -> lineEdit_11_ | F13: {=_xlfn.IFS(ROW()-1=1,-1,ROW()-1=ROWS(変換前のテーブル[index]),1,TRUE,0)} -> 0 | H13: en | I13: null | J13: han | M13: ="frame_"&INT((ROW()-2) / 3)&"_" -> frame_3_ | O13: ="frame__"&変換前のテーブル[[#This Row],[index]]&"__" -> frame__11__ | P13: horizontalLayout_4_ | R13: ="horizontalLayout__"&変換前のテーブル[[#This Row],[index]]&"__" -> horizontalLayout__11__ | T13: 404:薬剤式トイレ: 数量を入力（薬剤式トイレ） | U13: False | V13: True | X13: 404:薬剤式トイレ | AA13: True | BK13: =BK12+1 -> 11 | BL13: =変換前のテーブル[[#This Row],[list_item]] & "" | BM13: =SUBSTITUTE(SUBSTITUTE(SUBSTITUTE(_参照テーブル[[#This Row],[list]], "'", ""),"[", ""), "]", "") | BN13: {=MIN(VALUE(_xlfn.TEXTSPLIT(_参照テーブル[[#This Row],[conv]], ", ")))} -> #VALUE! | BO13: {=MAX(VALUE(_xlfn.TEXTSPLIT(_参照テーブル[[#This Row],[conv]], ", ")))} -> #VALUE! | BP13: =IFERROR("("&_参照テーブル[[#This Row],[min]]&"～"&_参照テーブル[[#This Row],[max]]&")","") | BQ13: =変換前のテーブル[[#This Row],[min_max]] -> 0 | BR13: =SUBSTITUTE(SUBSTITUTE(_参照テーブル[[#This Row],[list2]],"[",""),"]","") -> 0 | BS13: {=_xlfn.CHOOSECOLS(_xlfn.TEXTSPLIT(_参照テーブル[[#This Row],[list2_]],","),1)} -> 0 | BT13: {=_xlfn.CHOOSECOLS(_xlfn.TEXTSPLIT(_参照テーブル[[#This Row],[list2_]],","),2)} -> #VALUE! | BU13: =IFERROR("("&_参照テーブル[[#This Row],[min_]]&"～"&_参照テーブル[[#This Row],[max_]]&")", "")
A14: =ROW()-2 -> 12 | B14: =SUBSTITUTE(変換前のテーブル[[#This Row],[name]],"：",":")&":" -> 225:備蓄ランタン: | C14: hankaku-eisu-kuromaru | D14: ="label_"&変換前のテーブル[[#This Row],[index]]&"_" -> label_12_ | E14: ="lineEdit_"&変換前のテーブル[[#This Row],[index]]&"_" -> lineEdit_12_ | F14: {=_xlfn.IFS(ROW()-1=1,-1,ROW()-1=ROWS(変換前のテーブル[index]),1,TRUE,0)} -> 0 | H14: en | I14: null | J14: han | M14: ="frame_"&INT((ROW()-2) / 3)&"_" -> frame_4_ | O14: ="frame__"&変換前のテーブル[[#This Row],[index]]&"__" -> frame__12__ | P14: horizontalLayout_4_ | R14: ="horizontalLayout__"&変換前のテーブル[[#This Row],[index]]&"__" -> horizontalLayout__12__ | T14: 225:備蓄ランタン: 数量を入力（備蓄ランタン） | U14: False | V14: True | X14: 225:備蓄ランタン | BK14: =BK13+1 -> 12 | BL14: =変換前のテーブル[[#This Row],[list_item]] & "" | BM14: =SUBSTITUTE(SUBSTITUTE(SUBSTITUTE(_参照テーブル[[#This Row],[list]], "'", ""),"[", ""), "]", "") | BN14: {=MIN(VALUE(_xlfn.TEXTSPLIT(_参照テーブル[[#This Row],[conv]], ", ")))} -> #VALUE! | BO14: {=MAX(VALUE(_xlfn.TEXTSPLIT(_参照テーブル[[#This Row],[conv]], ", ")))} -> #VALUE! | BP14: =IFERROR("("&_参照テーブル[[#This Row],[min]]&"～"&_参照テーブル[[#This Row],[max]]&")","") | BQ14: =変換前のテーブル[[#This Row],[min_max]] -> 0 | BR14: =SUBSTITUTE(SUBSTITUTE(_参照テーブル[[#This Row],[list2]],"[",""),"]","") -> 0 | BS14: {=_xlfn.CHOOSECOLS(_xlfn.TEXTSPLIT(_参照テーブル[[#This Row],[list2_]],","),1)} -> 0 | BT14: {=_xlfn.CHOOSECOLS(_xlfn.TEXTSPLIT(_参照テーブル[[#This Row],[list2_]],","),2)} -> #VALUE! | BU14: =IFERROR("("&_参照テーブル[[#This Row],[min_]]&"～"&_参照テーブル[[#This Row],[max_]]&")", "")
A15: =ROW()-2 -> 13 | B15: =SUBSTITUTE(変換前のテーブル[[#This Row],[name]],"：",":")&":" -> 512:彩り主食: | C15: hankaku-eisu-kuromaru | D15: ="label_"&変換前のテーブル[[#This Row],[index]]&"_" -> label_13_ | E15: ="lineEdit_"&変換前のテーブル[[#This Row],[index]]&"_" -> lineEdit_13_ | F15: {=_xlfn.IFS(ROW()-1=1,-1,ROW()-1=ROWS(変換前のテーブル[index]),1,TRUE,0)} -> 0 | H15: en | I15: null | J15: han | M15: ="frame_"&INT((ROW()-2) / 3)&"_" -> frame_4_ | O15: ="frame__"&変換前のテーブル[[#This Row],[index]]&"__" -> frame__13__ | P15: horizontalLayout_4_ | R15: ="horizontalLayout__"&変換前のテーブル[[#This Row],[index]]&"__" -> horizontalLayout__13__ | T15: 512:彩り主食: 数量を入力（彩り主食） | U15: False | V15: True | X15: 512:彩り主食 | BK15: =BK14+1 -> 13 | BL15: =変換前のテーブル[[#This Row],[list_item]] & "" | BM15: =SUBSTITUTE(SUBSTITUTE(SUBSTITUTE(_参照テーブル[[#This Row],[list]], "'", ""),"[", ""), "]", "") | BN15: {=MIN(VALUE(_xlfn.TEXTSPLIT(_参照テーブル[[#This Row],[conv]], ", ")))} -> #VALUE! | BO15: {=MAX(VALUE(_xlfn.TEXTSPLIT(_参照テーブル[[#This Row],[conv]], ", ")))} -> #VALUE! | BP15: =IFERROR("("&_参照テーブル[[#This Row],[min]]&"～"&_参照テーブル[[#This Row],[max]]&")","") | BQ15: =変換前のテーブル[[#This Row],[min_max]] -> 0 | BR15: =SUBSTITUTE(SUBSTITUTE(_参照テーブル[[#This Row],[list2]],"[",""),"]","") -> 0 | BS15: {=_xlfn.CHOOSECOLS(_xlfn.TEXTSPLIT(_参照テーブル[[#This Row],[list2_]],","),1)} -> 0 | BT15: {=_xlfn.CHOOSECOLS(_xlfn.TEXTSPLIT(_参照テーブル[[#This Row],[list2_]],","),2)} -> #VALUE! | BU15: =IFERROR("("&_参照テーブル[[#This Row],[min_]]&"～"&_参照テーブル[[#This Row],[max_]]&")", "")
A16: =ROW()-2 -> 14 | B16: =SUBSTITUTE(変換前のテーブル[[#This Row],[name]],"：",":")&":" -> 411&415:全身きれい: | C16: hankaku-eisu-kuromaru | D16: ="label_"&変換前のテーブル[[#This Row],[index]]&"_" -> label_14_ | E16: ="lineEdit_"&変換前のテーブル[[#This Row],[index]]&"_" -> lineEdit_14_ | F16: {=_xlfn.IFS(ROW()-1=1,-1,ROW()-1=ROWS(変換前のテーブル[index]),1,TRUE,0)} -> 1 | H16: en | I16: null | J16: han | M16: ="frame_"&INT((ROW()-2) / 3)&"_" -> frame_4_ | O16: ="frame__"&変換前のテーブル[[#This Row],[index]]&"__" -> frame__14__ | P16: horizontalLayout_4_ | R16: ="horizontalLayout__"&変換前のテーブル[[#This Row],[index]]&"__" -> horizontalLayout__14__ | T16: 411&415:全身きれい: 数量を入力（全身きれい・歯みがき） | U16: False | V16: True | X16: 411&415:全身きれい | BK16: =BK15+1 -> 14 | BL16: =変換前のテーブル[[#This Row],[list_item]] & "" | BM16: =SUBSTITUTE(SUBSTITUTE(SUBSTITUTE(_参照テーブル[[#This Row],[list]], "'", ""),"[", ""), "]", "") | BN16: {=MIN(VALUE(_xlfn.TEXTSPLIT(_参照テーブル[[#This Row],[conv]], ", ")))} -> #VALUE! | BO16: {=MAX(VALUE(_xlfn.TEXTSPLIT(_参照テーブル[[#This Row],[conv]], ", ")))} -> #VALUE! | BP16: =IFERROR("("&_参照テーブル[[#This Row],[min]]&"～"&_参照テーブル[[#This Row],[max]]&")","") | BQ16: =変換前のテーブル[[#This Row],[min_max]] -> 0 | BR16: =SUBSTITUTE(SUBSTITUTE(_参照テーブル[[#This Row],[list2]],"[",""),"]","") -> 0 | BS16: {=_xlfn.CHOOSECOLS(_xlfn.TEXTSPLIT(_参照テーブル[[#This Row],[list2_]],","),1)} -> 0 | BT16: {=_xlfn.CHOOSECOLS(_xlfn.TEXTSPLIT(_参照テーブル[[#This Row],[list2_]],","),2)} -> #VALUE! | BU16: =IFERROR("("&_参照テーブル[[#This Row],[min_]]&"～"&_参照テーブル[[#This Row],[max_]]&")", "")
BK17: =BK16+1 -> 15 | BL17: =変換前のテーブル[[#This Row],[list_item]] & "" -> #VALUE! | BM17: =SUBSTITUTE(SUBSTITUTE(SUBSTITUTE(_参照テーブル[[#This Row],[list]], "'", ""),"[", ""), "]", "") -> #VALUE! | BN17: {=MIN(VALUE(_xlfn.TEXTSPLIT(_参照テーブル[[#This Row],[conv]], ", ")))} -> #VALUE! | BO17: {=MAX(VALUE(_xlfn.TEXTSPLIT(_参照テーブル[[#This Row],[conv]], ", ")))} -> #VALUE! | BP17: =IFERROR("("&_参照テーブル[[#This Row],[min]]&"～"&_参照テーブル[[#This Row],[max]]&")","") | BQ17: =変換前のテーブル[[#This Row],[min_max]] -> #VALUE! | BR17: =SUBSTITUTE(SUBSTITUTE(_参照テーブル[[#This Row],[list2]],"[",""),"]","") -> #VALUE! | BS17: {=_xlfn.CHOOSECOLS(_xlfn.TEXTSPLIT(_参照テーブル[[#This Row],[list2_]],","),1)} -> #VALUE! | BT17: {=_xlfn.CHOOSECOLS(_xlfn.TEXTSPLIT(_参照テーブル[[#This Row],[list2_]],","),2)} -> #VALUE! | BU17: =IFERROR("("&_参照テーブル[[#This Row],[min_]]&"～"&_参照テーブル[[#This Row],[max_]]&")", "")
BK18: =BK17+1 -> 16 | BL18: =変換前のテーブル[[#This Row],[list_item]] & "" -> #VALUE! | BM18: =SUBSTITUTE(SUBSTITUTE(SUBSTITUTE(_参照テーブル[[#This Row],[list]], "'", ""),"[", ""), "]", "") -> #VALUE! | BN18: {=MIN(VALUE(_xlfn.TEXTSPLIT(_参照テーブル[[#This Row],[conv]], ", ")))} -> #VALUE! | BO18: {=MAX(VALUE(_xlfn.TEXTSPLIT(_参照テーブル[[#This Row],[conv]], ", ")))} -> #VALUE! | BP18: =IFERROR("("&_参照テーブル[[#This Row],[min]]&"～"&_参照テーブル[[#This Row],[max]]&")","") | BQ18: =変換前のテーブル[[#This Row],[min_max]] -> #VALUE! | BR18: =SUBSTITUTE(SUBSTITUTE(_参照テーブル[[#This Row],[list2]],"[",""),"]","") -> #VALUE! | BS18: {=_xlfn.CHOOSECOLS(_xlfn.TEXTSPLIT(_参照テーブル[[#This Row],[list2_]],","),1)} -> #VALUE! | BT18: {=_xlfn.CHOOSECOLS(_xlfn.TEXTSPLIT(_参照テーブル[[#This Row],[list2_]],","),2)} -> #VALUE! | BU18: =IFERROR("("&_参照テーブル[[#This Row],[min_]]&"～"&_参照テーブル[[#This Row],[max_]]&")", "")
BK19: =BK18+1 -> 17 | BL19: =変換前のテーブル[[#This Row],[list_item]] & "" -> #VALUE! | BM19: =SUBSTITUTE(SUBSTITUTE(SUBSTITUTE(_参照テーブル[[#This Row],[list]], "'", ""),"[", ""), "]", "") -> #VALUE! | BN19: {=MIN(VALUE(_xlfn.TEXTSPLIT(_参照テーブル[[#This Row],[conv]], ", ")))} -> #VALUE! | BO19: {=MAX(VALUE(_xlfn.TEXTSPLIT(_参照テーブル[[#This Row],[conv]], ", ")))} -> #VALUE! | BP19: =IFERROR("("&_参照テーブル[[#This Row],[min]]&"～"&_参照テーブル[[#This Row],[max]]&")","") | BQ19: =変換前のテーブル[[#This Row],[min_max]] -> #VALUE! | BR19: =SUBSTITUTE(SUBSTITUTE(_参照テーブル[[#This Row],[list2]],"[",""),"]","") -> #VALUE! | BS19: {=_xlfn.CHOOSECOLS(_xlfn.TEXTSPLIT(_参照テーブル[[#This Row],[list2_]],","),1)} -> #VALUE! | BT19: {=_xlfn.CHOOSECOLS(_xlfn.TEXTSPLIT(_参照テーブル[[#This Row],[list2_]],","),2)} -> #VALUE! | BU19: =IFERROR("("&_参照テーブル[[#This Row],[min_]]&"～"&_参照テーブル[[#This Row],[max_]]&")", "")
BK20: =BK19+1 -> 18 | BL20: =変換前のテーブル[[#This Row],[list_item]] & "" -> #VALUE! | BM20: =SUBSTITUTE(SUBSTITUTE(SUBSTITUTE(_参照テーブル[[#This Row],[list]], "'", ""),"[", ""), "]", "") -> #VALUE! | BN20: {=MIN(VALUE(_xlfn.TEXTSPLIT(_参照テーブル[[#This Row],[conv]], ", ")))} -> #VALUE! | BO20: {=MAX(VALUE(_xlfn.TEXTSPLIT(_参照テーブル[[#This Row],[conv]], ", ")))} -> #VALUE! | BP20: =IFERROR("("&_参照テーブル[[#This Row],[min]]&"～"&_参照テーブル[[#This Row],[max]]&")","") | BQ20: =変換前のテーブル[[#This Row],[min_max]] -> #VALUE! | BR20: =SUBSTITUTE(SUBSTITUTE(_参照テーブル[[#This Row],[list2]],"[",""),"]","") -> #VALUE! | BS20: {=_xlfn.CHOOSECOLS(_xlfn.TEXTSPLIT(_参照テーブル[[#This Row],[list2_]],","),1)} -> #VALUE! | BT20: {=_xlfn.CHOOSECOLS(_xlfn.TEXTSPLIT(_参照テーブル[[#This Row],[list2_]],","),2)} -> #VALUE! | BU20: =IFERROR("("&_参照テーブル[[#This Row],[min_]]&"～"&_参照テーブル[[#This Row],[max_]]&")", "")
BK21: =BK20+1 -> 19 | BL21: =変換前のテーブル[[#This Row],[list_item]] & "" -> #VALUE! | BM21: =SUBSTITUTE(SUBSTITUTE(SUBSTITUTE(_参照テーブル[[#This Row],[list]], "'", ""),"[", ""), "]", "") -> #VALUE! | BN21: {=MIN(VALUE(_xlfn.TEXTSPLIT(_参照テーブル[[#This Row],[conv]], ", ")))} -> #VALUE! | BO21: {=MAX(VALUE(_xlfn.TEXTSPLIT(_参照テーブル[[#This Row],[conv]], ", ")))} -> #VALUE! | BP21: =IFERROR("("&_参照テーブル[[#This Row],[min]]&"～"&_参照テーブル[[#This Row],[max]]&")","") | BQ21: =変換前のテーブル[[#This Row],[min_max]] -> #VALUE! | BR21: =SUBSTITUTE(SUBSTITUTE(_参照テーブル[[#This Row],[list2]],"[",""),"]","") -> #VALUE! | BS21: {=_xlfn.CHOOSECOLS(_xlfn.TEXTSPLIT(_参照テーブル[[#This Row],[list2_]],","),1)} -> #VALUE! | BT21: {=_xlfn.CHOOSECOLS(_xlfn.TEXTSPLIT(_参照テーブル[[#This Row],[list2_]],","),2)} -> #VALUE! | BU21: =IFERROR("("&_参照テーブル[[#This Row],[min_]]&"～"&_参照テーブル[[#This Row],[max_]]&")", "")
BK22: =BK21+1 -> 20 | BL22: =変換前のテーブル[[#This Row],[list_item]] & "" -> #VALUE! | BM22: =SUBSTITUTE(SUBSTITUTE(SUBSTITUTE(_参照テーブル[[#This Row],[list]], "'", ""),"[", ""), "]", "") -> #VALUE! | BN22: {=MIN(VALUE(_xlfn.TEXTSPLIT(_参照テーブル[[#This Row],[conv]], ", ")))} -> #VALUE! | BO22: {=MAX(VALUE(_xlfn.TEXTSPLIT(_参照テーブル[[#This Row],[conv]], ", ")))} -> #VALUE! | BP22: =IFERROR("("&_参照テーブル[[#This Row],[min]]&"～"&_参照テーブル[[#This Row],[max]]&")","") | BQ22: =変換前のテーブル[[#This Row],[min_max]] -> #VALUE! | BR22: =SUBSTITUTE(SUBSTITUTE(_参照テーブル[[#This Row],[list2]],"[",""),"]","") -> #VALUE! | BS22: {=_xlfn.CHOOSECOLS(_xlfn.TEXTSPLIT(_参照テーブル[[#This Row],[list2_]],","),1)} -> #VALUE! | BT22: {=_xlfn.CHOOSECOLS(_xlfn.TEXTSPLIT(_参照テーブル[[#This Row],[list2_]],","),2)} -> #VALUE! | BU22: =IFERROR("("&_参照テーブル[[#This Row],[min_]]&"～"&_参照テーブル[[#This Row],[max_]]&")", "")
BK23: =BK22+1 -> 21 | BL23: =変換前のテーブル[[#This Row],[list_item]] & "" -> #VALUE! | BM23: =SUBSTITUTE(SUBSTITUTE(SUBSTITUTE(_参照テーブル[[#This Row],[list]], "'", ""),"[", ""), "]", "") -> #VALUE! | BN23: {=MIN(VALUE(_xlfn.TEXTSPLIT(_参照テーブル[[#This Row],[conv]], ", ")))} -> #VALUE! | BO23: {=MAX(VALUE(_xlfn.TEXTSPLIT(_参照テーブル[[#This Row],[conv]], ", ")))} -> #VALUE! | BP23: =IFERROR("("&_参照テーブル[[#This Row],[min]]&"～"&_参照テーブル[[#This Row],[max]]&")","") | BQ23: =変換前のテーブル[[#This Row],[min_max]] -> #VALUE! | BR23: =SUBSTITUTE(SUBSTITUTE(_参照テーブル[[#This Row],[list2]],"[",""),"]","") -> #VALUE! | BS23: {=_xlfn.CHOOSECOLS(_xlfn.TEXTSPLIT(_参照テーブル[[#This Row],[list2_]],","),1)} -> #VALUE! | BT23: {=_xlfn.CHOOSECOLS(_xlfn.TEXTSPLIT(_参照テーブル[[#This Row],[list2_]],","),2)} -> #VALUE! | BU23: =IFERROR("("&_参照テーブル[[#This Row],[min_]]&"～"&_参照テーブル[[#This Row],[max_]]&")", "")
BK24: =BK23+1 -> 22 | BL24: =変換前のテーブル[[#This Row],[list_item]] & "" -> #VALUE! | BM24: =SUBSTITUTE(SUBSTITUTE(SUBSTITUTE(_参照テーブル[[#This Row],[list]], "'", ""),"[", ""), "]", "") -> #VALUE! | BN24: {=MIN(VALUE(_xlfn.TEXTSPLIT(_参照テーブル[[#This Row],[conv]], ", ")))} -> #VALUE! | BO24: {=MAX(VALUE(_xlfn.TEXTSPLIT(_参照テーブル[[#This Row],[conv]], ", ")))} -> #VALUE! | BP24: =IFERROR("("&_参照テーブル[[#This Row],[min]]&"～"&_参照テーブル[[#This Row],[max]]&")","") | BQ24: =変換前のテーブル[[#This Row],[min_max]] -> #VALUE! | BR24: =SUBSTITUTE(SUBSTITUTE(_参照テーブル[[#This Row],[list2]],"[",""),"]","") -> #VALUE! | BS24: {=_xlfn.CHOOSECOLS(_xlfn.TEXTSPLIT(_参照テーブル[[#This Row],[list2_]],","),1)} -> #VALUE! | BT24: {=_xlfn.CHOOSECOLS(_xlfn.TEXTSPLIT(_参照テーブル[[#This Row],[list2_]],","),2)} -> #VALUE! | BU24: =IFERROR("("&_参照テーブル[[#This Row],[min_]]&"～"&_参照テーブル[[#This Row],[max_]]&")", "")
BK25: =BK24+1 -> 23 | BL25: =変換前のテーブル[[#This Row],[list_item]] & "" -> #VALUE! | BM25: =SUBSTITUTE(SUBSTITUTE(SUBSTITUTE(_参照テーブル[[#This Row],[list]], "'", ""),"[", ""), "]", "") -> #VALUE! | BN25: {=MIN(VALUE(_xlfn.TEXTSPLIT(_参照テーブル[[#This Row],[conv]], ", ")))} -> #VALUE! | BO25: {=MAX(VALUE(_xlfn.TEXTSPLIT(_参照テーブル[[#This Row],[conv]], ", ")))} -> #VALUE! | BP25: =IFERROR("("&_参照テーブル[[#This Row],[min]]&"～"&_参照テーブル[[#This Row],[max]]&")","") | BQ25: =変換前のテーブル[[#This Row],[min_max]] -> #VALUE! | BR25: =SUBSTITUTE(SUBSTITUTE(_参照テーブル[[#This Row],[list2]],"[",""),"]","") -> #VALUE! | BS25: {=_xlfn.CHOOSECOLS(_xlfn.TEXTSPLIT(_参照テーブル[[#This Row],[list2_]],","),1)} -> #VALUE! | BT25: {=_xlfn.CHOOSECOLS(_xlfn.TEXTSPLIT(_参照テーブル[[#This Row],[list2_]],","),2)} -> #VALUE! | BU25: =IFERROR("("&_参照テーブル[[#This Row],[min_]]&"～"&_参照テーブル[[#This Row],[max_]]&")", "")
BK26: =BK25+1 -> 24 | BL26: =変換前のテーブル[[#This Row],[list_item]] & "" -> #VALUE! | BM26: =SUBSTITUTE(SUBSTITUTE(SUBSTITUTE(_参照テーブル[[#This Row],[list]], "'", ""),"[", ""), "]", "") -> #VALUE! | BN26: {=MIN(VALUE(_xlfn.TEXTSPLIT(_参照テーブル[[#This Row],[conv]], ", ")))} -> #VALUE! | BO26: {=MAX(VALUE(_xlfn.TEXTSPLIT(_参照テーブル[[#This Row],[conv]], ", ")))} -> #VALUE! | BP26: =IFERROR("("&_参照テーブル[[#This Row],[min]]&"～"&_参照テーブル[[#This Row],[max]]&")","") | BQ26: =変換前のテーブル[[#This Row],[min_max]] -> #VALUE! | BR26: =SUBSTITUTE(SUBSTITUTE(_参照テーブル[[#This Row],[list2]],"[",""),"]","") -> #VALUE! | BS26: {=_xlfn.CHOOSECOLS(_xlfn.TEXTSPLIT(_参照テーブル[[#This Row],[list2_]],","),1)} -> #VALUE! | BT26: {=_xlfn.CHOOSECOLS(_xlfn.TEXTSPLIT(_参照テーブル[[#This Row],[list2_]],","),2)} -> #VALUE! | BU26: =IFERROR("("&_参照テーブル[[#This Row],[min_]]&"～"&_参照テーブル[[#This Row],[max_]]&")", "")
BK27: =BK26+1 -> 25 | BL27: =変換前のテーブル[[#This Row],[list_item]] & "" -> #VALUE! | BM27: =SUBSTITUTE(SUBSTITUTE(SUBSTITUTE(_参照テーブル[[#This Row],[list]], "'", ""),"[", ""), "]", "") -> #VALUE! | BN27: {=MIN(VALUE(_xlfn.TEXTSPLIT(_参照テーブル[[#This Row],[conv]], ", ")))} -> #VALUE! | BO27: {=MAX(VALUE(_xlfn.TEXTSPLIT(_参照テーブル[[#This Row],[conv]], ", ")))} -> #VALUE! | BP27: =IFERROR("("&_参照テーブル[[#This Row],[min]]&"～"&_参照テーブル[[#This Row],[max]]&")","") | BQ27: =変換前のテーブル[[#This Row],[min_max]] -> #VALUE! | BR27: =SUBSTITUTE(SUBSTITUTE(_参照テーブル[[#This Row],[list2]],"[",""),"]","") -> #VALUE! | BS27: {=_xlfn.CHOOSECOLS(_xlfn.TEXTSPLIT(_参照テーブル[[#This Row],[list2_]],","),1)} -> #VALUE! | BT27: {=_xlfn.CHOOSECOLS(_xlfn.TEXTSPLIT(_参照テーブル[[#This Row],[list2_]],","),2)} -> #VALUE! | BU27: =IFERROR("("&_参照テーブル[[#This Row],[min_]]&"～"&_参照テーブル[[#This Row],[max_]]&")", "")
BK28: =BK27+1 -> 26 | BL28: =変換前のテーブル[[#This Row],[list_item]] & "" -> #VALUE! | BM28: =SUBSTITUTE(SUBSTITUTE(SUBSTITUTE(_参照テーブル[[#This Row],[list]], "'", ""),"[", ""), "]", "") -> #VALUE! | BN28: {=MIN(VALUE(_xlfn.TEXTSPLIT(_参照テーブル[[#This Row],[conv]], ", ")))} -> #VALUE! | BO28: {=MAX(VALUE(_xlfn.TEXTSPLIT(_参照テーブル[[#This Row],[conv]], ", ")))} -> #VALUE! | BP28: =IFERROR("("&_参照テーブル[[#This Row],[min]]&"～"&_参照テーブル[[#This Row],[max]]&")","") | BQ28: =変換前のテーブル[[#This Row],[min_max]] -> #VALUE! | BR28: =SUBSTITUTE(SUBSTITUTE(_参照テーブル[[#This Row],[list2]],"[",""),"]","") -> #VALUE! | BS28: {=_xlfn.CHOOSECOLS(_xlfn.TEXTSPLIT(_参照テーブル[[#This Row],[list2_]],","),1)} -> #VALUE! | BT28: {=_xlfn.CHOOSECOLS(_xlfn.TEXTSPLIT(_参照テーブル[[#This Row],[list2_]],","),2)} -> #VALUE! | BU28: =IFERROR("("&_参照テーブル[[#This Row],[min_]]&"～"&_参照テーブル[[#This Row],[max_]]&")", "")
... BK133: =BK132+1 -> 131 | BL133: =変換前のテーブル[[#This Row],[list_item]] & "" -> #VALUE! | BM133: =SUBSTITUTE(SUBSTITUTE(SUBSTITUTE(_参照テーブル[[#This Row],[list]], "'", ""),"[", ""), "]", "") -> #VALUE! | BN133: {=MIN(VALUE(_xlfn.TEXTSPLIT(_参照テーブル[[#This Row],[conv]], ", ")))} -> #VALUE! | BO133: {=MAX(VALUE(_xlfn.TEXTSPLIT(_参照テーブル[[#This Row],[conv]], ", ")))} -> #VALUE! | BP133: =IFERROR("("&_参照テーブル[[#This Row],[min]]&"～"&_参照テーブル[[#This Row],[max]]&")","") | BQ133: =変換前のテーブル[[#This Row],[min_max]] -> #VALUE! | BR133: =SUBSTITUTE(SUBSTITUTE(_参照テーブル[[#This Row],[list2]],"[",""),"]","") -> #VALUE! | BS133: {=_xlfn.CHOOSECOLS(_xlfn.TEXTSPLIT(_参照テーブル[[#This Row],[list2_]],","),1)} -> #VALUE! | BT133: {=_xlfn.CHOOSECOLS(_xlfn.TEXTSPLIT(_参照テーブル[[#This Row],[list2_]],","),2)} -> #VALUE! | BU133: =IFERROR("("&_参照テーブル[[#This Row],[min_]]&"～"&_参照テーブル[[#This Row],[max_]]&")", "")

Sheet result
A2: ="{"&_xlfn.TEXTJOIN(", ",TRUE,calcu2!A2:AZ2)&"}," -> {'index': 0, 'display_name': 'ID:', 'data_type': 'hankaku-eisu-kuromaru_lenjust', 'label_name': 'label_0_', 'line_edit_name': 'lineEdit_0_', 'is_last': -1, 'line_edit_obj': '', 'ime_mode': 'en', 'pn_auto_input': 'null', 'text_conversion': '', 'label_obj': '', 'frame_a_obj': '', 'frame_a_name': 'frame_0_', 'frame_b_obj': '', 'frame_b_name': 'frame__0__', 'layout_a_name': 'horizontalLayout_0_', 'layout_a_obj': '', 'layout_b_name': 'horizontalLayout__0__', 'layout_b_obj': '', 'info': 'ID: 数字10桁', 'is_rept': False, 'is_show': True, 'list_item': 0, 'name': 'ID', 'replace_keys': 0, 'replace_values': 0, 'is_b_line_show': 0, 'length': 10, 'min_max': 0, 're': '', 'remarks': 0},
A3: ="{"&_xlfn.TEXTJOIN(", ",TRUE,calcu2!A3:AZ3)&"}," -> {'index': 1, 'display_name': '登録情報:', 'data_type': 'hankaku-eisu-kuromaru', 'label_name': 'label_1_', 'line_edit_name': 'lineEdit_1_', 'is_last': 0, 'line_edit_obj': '', 'ime_mode': 'en', 'pn_auto_input': 'null', 'text_conversion': '', 'label_obj': '', 'frame_a_obj': '', 'frame_a_name': 'frame_0_', 'frame_b_obj': '', 'frame_b_name': 'frame__1__', 'layout_a_name': 'horizontalLayout_0_', 'layout_a_obj': '', 'layout_b_name': 'horizontalLayout__1__', 'layout_b_obj': '', 'info': '登録情報: 変更なし=1 変更あり=2', 'is_rept': False, 'is_show': True, 'list_item': 0, 'name': '登録情報', 'replace_keys': 0, 'replace_values': 0, 'is_b_line_show': 0, 'length': 0, 'min_max': 0, 're': '', 'remarks': 0},
A4: ="{"&_xlfn.TEXTJOIN(", ",TRUE,calcu2!A4:AZ4)&"}," -> {'index': 2, 'display_name': '郵便番号:', 'data_type': 'hankaku-eisu-kuromaru', 'label_name': 'label_2_', 'line_edit_name': 'lineEdit_2_', 'is_last': 0, 'line_edit_obj': '', 'ime_mode': 'en', 'pn_auto_input': 'postnum', 'text_conversion': 'han', 'label_obj': '', 'frame_a_obj': '', 'frame_a_name': 'frame_0_', 'frame_b_obj': '', 'frame_b_name': 'frame__2__', 'layout_a_name': 'horizontalLayout_1_', 'layout_a_obj': '', 'layout_b_name': 'horizontalLayout__2__', 'layout_b_obj': '', 'info': '郵便番号: ハイフンなし7桁', 'is_rept': False, 'is_show': True, 'list_item': 0, 'name': '郵便番号', 'replace_keys': 0, 'replace_values': 0, 'is_b_line_show': True, 'length': 0, 'min_max': 0, 're': '', 'remarks': 0},
A5: ="{"&_xlfn.TEXTJOIN(", ",TRUE,calcu2!A5:AZ5)&"}," -> {'index': 3, 'display_name': '都道府県:', 'data_type': 'str', 'label_name': 'label_3_', 'line_edit_name': 'lineEdit_3_', 'is_last': 0, 'line_edit_obj': '', 'ime_mode': 'jp', 'pn_auto_input': 'pref', 'text_conversion': 'han-ans', 'label_obj': '', 'frame_a_obj': '', 'frame_a_name': 'frame_1_', 'frame_b_obj': '', 'frame_b_name': 'frame__3__', 'layout_a_name': 'horizontalLayout_1_', 'layout_a_obj': '', 'layout_b_name': 'horizontalLayout__3__', 'layout_b_obj': '', 'info': '都道府県: ', 'is_rept': False, 'is_show': True, 'list_item': 0, 'name': '都道府県', 'replace_keys': 0, 'replace_values': 0, 'is_b_line_show': 0, 'length': 0, 'min_max': 0, 're': '', 'remarks': 0},
A6: ="{"&_xlfn.TEXTJOIN(", ",TRUE,calcu2!A6:AZ6)&"}," -> {'index': 4, 'display_name': '市区町村:', 'data_type': 'str', 'label_name': 'label_4_', 'line_edit_name': 'lineEdit_4_', 'is_last': 0, 'line_edit_obj': '', 'ime_mode': 'jp', 'pn_auto_input': 'city', 'text_conversion': 'han-ans', 'label_obj': '', 'frame_a_obj': '', 'frame_a_name': 'frame_1_', 'frame_b_obj': '', 'frame_b_name': 'frame__4__', 'layout_a_name': 'horizontalLayout_1_', 'layout_a_obj': '', 'layout_b_name': 'horizontalLayout__4__', 'layout_b_obj': '', 'info': '市区町村: ', 'is_rept': False, 'is_show': True, 'list_item': 0, 'name': '市区町村', 'replace_keys': 0, 'replace_values': 0, 'is_b_line_show': 0, 'length': 0, 'min_max': 0, 're': '', 'remarks': 0},
A7: ="{"&_xlfn.TEXTJOIN(", ",TRUE,calcu2!A7:AZ7)&"}," -> {'index': 5, 'display_name': '町域番地:', 'data_type': 'str', 'label_name': 'label_5_', 'line_edit_name': 'lineEdit_5_', 'is_last': 0, 'line_edit_obj': '', 'ime_mode': 'jp', 'pn_auto_input': 'town', 'text_conversion': 'han-ans', 'label_obj': '', 'frame_a_obj': '', 'frame_a_name': 'frame_1_', 'frame_b_obj': '', 'frame_b_name': 'frame__5__', 'layout_a_name': 'horizontalLayout_2_', 'layout_a_obj': '', 'layout_b_name': 'horizontalLayout__5__', 'layout_b_obj': '', 'info': '町域番地: ', 'is_rept': False, 'is_show': True, 'list_item': 0, 'name': '町域番地', 'replace_keys': 0, 'replace_values': 0, 'is_b_line_show': 0, 'length': 0, 'min_max': 0, 're': '', 'remarks': 0},
A8: ="{"&_xlfn.TEXTJOIN(", ",TRUE,calcu2!A8:AZ8)&"}," -> {'index': 6, 'display_name': '建物:', 'data_type': 'str', 'label_name': 'label_6_', 'line_edit_name': 'lineEdit_6_', 'is_last': 0, 'line_edit_obj': '', 'ime_mode': 'jp', 'pn_auto_input': 'null', 'text_conversion': 'han-ans', 'label_obj': '', 'frame_a_obj': '', 'frame_a_name': 'frame_2_', 'frame_b_obj': '', 'frame_b_name': 'frame__6__', 'layout_a_name': 'horizontalLayout_2_', 'layout_a_obj': '', 'layout_b_name': 'horizontalLayout__6__', 'layout_b_obj': '', 'info': '建物: ', 'is_rept': False, 'is_show': True, 'list_item': 0, 'name': '建物', 'replace_keys': 0, 'replace_values': 0, 'is_b_line_show': 0, 'length': 0, 'min_max': 0, 're': '', 'remarks': 0},
A9: ="{"&_xlfn.TEXTJOIN(", ",TRUE,calcu2!A9:AZ9)&"}," -> {'index': 7, 'display_name': '氏名かな:', 'data_type': 'str', 'label_name': 'label_7_', 'line_edit_name': 'lineEdit_7_', 'is_last': 0, 'line_edit_obj': '', 'ime_mode': 'jp', 'pn_auto_input': 'null', 'text_conversion': '', 'label_obj': '', 'frame_a_obj': '', 'frame_a_name': 'frame_2_', 'frame_b_obj': '', 'frame_b_name': 'frame__7__', 'layout_a_name': 'horizontalLayout_3_', 'layout_a_obj': '', 'layout_b_name': 'horizontalLayout__7__', 'layout_b_obj': '', 'info': '氏名かな: ひらがな スペースあり', 'is_rept': False, 'is_show': True, 'list_item': 0, 'name': '氏名かな', 'replace_keys': 0, 'replace_values': 0, 'is_b_line_show': True, 'length': 0, 'min_max': 0, 're': '', 'remarks': 0},
A10: ="{"&_xlfn.TEXTJOIN(", ",TRUE,calcu2!A10:AZ10)&"}," -> {'index': 8, 'display_name': '氏名:', 'data_type': 'str', 'label_name': 'label_8_', 'line_edit_name': 'lineEdit_8_', 'is_last': 0, 'line_edit_obj': '', 'ime_mode': 'jp', 'pn_auto_input': 'null', 'text_conversion': '', 'label_obj': '', 'frame_a_obj': '', 'frame_a_name': 'frame_2_', 'frame_b_obj': '', 'frame_b_name': 'frame__8__', 'layout_a_name': 'horizontalLayout_3_', 'layout_a_obj': '', 'layout_b_name': 'horizontalLayout__8__', 'layout_b_obj': '', 'info': '氏名: スペースあり', 'is_rept': False, 'is_show': True, 'list_item': 0, 'name': '氏名', 'replace_keys': 0, 'replace_values': 0, 'is_b_line_show': 0, 'length': 0, 'min_max': 0, 're': '', 'remarks': 0},
A11: ="{"&_xlfn.TEXTJOIN(", ",TRUE,calcu2!A11:AZ11)&"}," -> {'index': 9, 'display_name': '電話番号:', 'data_type': 'hankaku-eisu-kuromaru_lenrange', 'label_name': 'label_9_', 'line_edit_name': 'lineEdit_9_', 'is_last': 0, 'line_edit_obj': '', 'ime_mode': 'en', 'pn_auto_input': 'null', 'text_conversion': 'han', 'label_obj': '', 'frame_a_obj': '', 'frame_a_name': 'frame_3_', 'frame_b_obj': '', 'frame_b_name': 'frame__9__', 'layout_a_name': 'horizontalLayout_3_', 'layout_a_obj': '', 'layout_b_name': 'horizontalLayout__9__', 'layout_b_obj': '', 'info': '電話番号: ハイフンなし 桁数:10～11', 'is_rept': False, 'is_show': True, 'list_item': 0, 'name': '電話番号', 'replace_keys': 0, 'replace_values': 0, 'is_b_line_show': True, 'length': [10, 11], 'min_max': 0, 're': '', 'remarks': 0},
A12: ="{"&_xlfn.TEXTJOIN(", ",TRUE,calcu2!A12:AZ12)&"}," -> {'index': 10, 'display_name': '防災カルタ:', 'data_type': 'hankaku-eisu-kuromaru', 'label_name': 'label_10_', 'line_edit_name': 'lineEdit_10_', 'is_last': 0, 'line_edit_obj': '', 'ime_mode': 'en', 'pn_auto_input': 'null', 'text_conversion': 'han', 'label_obj': '', 'frame_a_obj': '', 'frame_a_name': 'frame_3_', 'frame_b_obj': '', 'frame_b_name': 'frame__10__', 'layout_a_name': 'horizontalLayout_3_', 'layout_a_obj': '', 'layout_b_name': 'horizontalLayout__10__', 'layout_b_obj': '', 'info': '防災カルタ: 申し込む=1 不要=2', 'is_rept': False, 'is_show': True, 'list_item': 0, 'name': '防災カルタ', 'replace_keys': 0, 'replace_values': 0, 'is_b_line_show': 0, 'length': 0, 'min_max': 0, 're': '', 'remarks': 0},
A13: ="{"&_xlfn.TEXTJOIN(", ",TRUE,calcu2!A13:AZ13)&"}," -> {'index': 11, 'display_name': '404:薬剤式トイレ:', 'data_type': 'hankaku-eisu-kuromaru', 'label_name': 'label_11_', 'line_edit_name': 'lineEdit_11_', 'is_last': 0, 'line_edit_obj': '', 'ime_mode': 'en', 'pn_auto_input': 'null', 'text_conversion': 'han', 'label_obj': '', 'frame_a_obj': '', 'frame_a_name': 'frame_3_', 'frame_b_obj': '', 'frame_b_name': 'frame__11__', 'layout_a_name': 'horizontalLayout_4_', 'layout_a_obj': '', 'layout_b_name': 'horizontalLayout__11__', 'layout_b_obj': '', 'info': '404:薬剤式トイレ: 数量を入力（薬剤式トイレ）', 'is_rept': False, 'is_show': True, 'list_item': 0, 'name': '404:薬剤式トイレ', 'replace_keys': 0, 'replace_values': 0, 'is_b_line_show': True, 'length': 0, 'min_max': 0, 're': '', 'remarks': 0},
... A261: ="{"&_xlfn.TEXTJOIN(", ",TRUE,calcu2!A261:AZ261)&"}," -> {},

Sheet calcu1
A1: {=変換前のテーブル[#Headers]} -> index | B1: display_name | C1: data_type | D1: label_name | E1: line_edit_name | F1: is_last | G1: line_edit_obj | H1: ime_mode | I1: pn_auto_input | J1: text_conversion | K1: label_obj | L1: frame_a_obj | M1: frame_a_name | N1: frame_b_obj | O1: frame_b_name | P1: layout_a_name | Q1: layout_a_obj | R1: layout_b_name | S1: layout_b_obj | T1: info | U1: is_rept | V1: is_show | W1: list_item | X1: name | Y1: replace_keys | Z1: replace_values | AA1: is_b_line_show | AB1: length | AC1: min_max | AD1: re | AE1: remarks
A2: {=_xlfn.LET(_xlpm._HasQuote, _xlfn.XLOOKUP(A$1,_xlfn.ANCHORARRAY(config!$U$5),_xlfn.ANCHORARRAY(config!$V$5),FALSE), _xlpm._Indirect, INDIRECT("変換前のテーブル[["&A$1&"]]"), _xlpm._Result, IF(_xlpm._HasQuote,"'"&_xlpm._Indirect&"'",_xlpm._Indirect), _xlpm._Result )} -> 0 | B2: {=_xlfn.LET(_xlpm._HasQuote, _xlfn.XLOOKUP(B$1,_xlfn.ANCHORARRAY(config!$U$5),_xlfn.ANCHORARRAY(config!$V$5),FALSE), _xlpm._Indirect, INDIRECT("変換前のテーブル[["&B$1&"]]"), _xlpm._Result, IF(_xlpm._HasQuote,"'"&_xlpm._Indirect&"'",_xlpm._Indirect), _xlpm._Result )} -> 'ID:' | C2: {=_xlfn.LET(_xlpm._HasQuote, _xlfn.XLOOKUP(C$1,_xlfn.ANCHORARRAY(config!$U$5),_xlfn.ANCHORARRAY(config!$V$5),FALSE), _xlpm._Indirect, INDIRECT("変換前のテーブル[["&C$1&"]]"), _xlpm._Result, IF(_xlpm._HasQuote,"'"&_xlpm._Indirect&"'",_xlpm._Indirect), _xlpm._Result )} -> 'hankaku-eisu-kuromaru_lenjust' | D2: {=_xlfn.LET(_xlpm._HasQuote, _xlfn.XLOOKUP(D$1,_xlfn.ANCHORARRAY(config!$U$5),_xlfn.ANCHORARRAY(config!$V$5),FALSE), _xlpm._Indirect, INDIRECT("変換前のテーブル[["&D$1&"]]"), _xlpm._Result, IF(_xlpm._HasQuote,"'"&_xlpm._Indirect&"'",_xlpm._Indirect), _xlpm._Result )} -> 'label_0_' | E2: {=_xlfn.LET(_xlpm._HasQuote, _xlfn.XLOOKUP(E$1,_xlfn.ANCHORARRAY(config!$U$5),_xlfn.ANCHORARRAY(config!$V$5),FALSE), _xlpm._Indirect, INDIRECT("変換前のテーブル[["&E$1&"]]"), _xlpm._Result, IF(_xlpm._HasQuote,"'"&_xlpm._Indirect&"'",_xlpm._Indirect), _xlpm._Result )} -> 'lineEdit_0_' | F2: {=_xlfn.LET(_xlpm._HasQuote, _xlfn.XLOOKUP(F$1,_xlfn.ANCHORARRAY(config!$U$5),_xlfn.ANCHORARRAY(config!$V$5),FALSE), _xlpm._Indirect, INDIRECT("変換前のテーブル[["&F$1&"]]"), _xlpm._Result, IF(_xlpm._HasQuote,"'"&_xlpm._Indirect&"'",_xlpm._Indirect), _xlpm._Result )} -> -1 | G2: {=_xlfn.LET(_xlpm._HasQuote, _xlfn.XLOOKUP(G$1,_xlfn.ANCHORARRAY(config!$U$5),_xlfn.ANCHORARRAY(config!$V$5),FALSE), _xlpm._Indirect, INDIRECT("変換前のテーブル[["&G$1&"]]"), _xlpm._Result, IF(_xlpm._HasQuote,"'"&_xlpm._Indirect&"'",_xlpm._Indirect), _xlpm._Result )} -> '' | H2: {=_xlfn.LET(_xlpm._HasQuote, _xlfn.XLOOKUP(H$1,_xlfn.ANCHORARRAY(config!$U$5),_xlfn.ANCHORARRAY(config!$V$5),FALSE), _xlpm._Indirect, INDIRECT("変換前のテーブル[["&H$1&"]]"), _xlpm._Result, IF(_xlpm._HasQuote,"'"&_xlpm._Indirect&"'",_xlpm._Indirect), _xlpm._Result )} -> 'en' | ... AM2: {=_xlfn.LET(_xlpm._HasQuote, _xlfn.XLOOKUP(AM$1,_xlfn.ANCHORARRAY(config!$U$5),_xlfn.ANCHORARRAY(config!$V$5),FALSE), _xlpm._Indirect, INDIRECT("変換前のテーブル[["&AM$1&"]]"), _xlpm._Result, IF(_xlpm._HasQuote,"'"&_xlpm._Indirect&"'",_xlpm._Indirect), _xlpm._Result )} -> #REF!
A3: 1 | B3: '登録情報:' | C3: 'hankaku-eisu-kuromaru' | D3: 'label_1_' | E3: 'lineEdit_1_' | F3: 0 | G3: '' | H3: 'en' | I3: 'null' | J3: '' | K3: '' | L3: '' | M3: 'frame_0_' | N3: '' | O3: 'frame__1__' | P3: 'horizontalLayout_0_' | Q3: '' | R3: 'horizontalLayout__1__' | S3: '' | T3: '登録情報: 変更なし=1 変更あり=2' | U3: False | V3: True | W3: 0 | X3: '登録情報' | Y3: 0 | Z3: 0 | AA3: 0 | AB3: 0 | AC3: 0 | AD3: '' | AE3: 0
A4: 2 | B4: '郵便番号:' | C4: 'hankaku-eisu-kuromaru' | D4: 'label_2_' | E4: 'lineEdit_2_' | F4: 0 | G4: '' | H4: 'en' | I4: 'postnum' | J4: 'han' | K4: '' | L4: '' | M4: 'frame_0_' | N4: '' | O4: 'frame__2__' | P4: 'horizontalLayout_1_' | Q4: '' | R4: 'horizontalLayout__2__' | S4: '' | T4: '郵便番号: ハイフンなし7桁' | U4: False | V4: True | W4: 0 | X4: '郵便番号' | Y4: 0 | Z4: 0 | AA4: True | AB4: 0 | AC4: 0 | AD4: '' | AE4: 0
A5: 3 | B5: '都道府県:' | C5: 'str' | D5: 'label_3_' | E5: 'lineEdit_3_' | F5: 0 | G5: '' | H5: 'jp' | I5: 'pref' | J5: 'han-ans' | K5: '' | L5: '' | M5: 'frame_1_' | N5: '' | O5: 'frame__3__' | P5: 'horizontalLayout_1_' | Q5: '' | R5: 'horizontalLayout__3__' | S5: '' | T5: '都道府県: ' | U5: False | V5: True | W5: 0 | X5: '都道府県' | Y5: 0 | Z5: 0 | AA5: 0 | AB5: 0 | AC5: 0 | AD5: '' | AE5: 0
A6: 4 | B6: '市区町村:' | C6: 'str' | D6: 'label_4_' | E6: 'lineEdit_4_' | F6: 0 | G6: '' | H6: 'jp' | I6: 'city' | J6: 'han-ans' | K6: '' | L6: '' | M6: 'frame_1_' | N6: '' | O6: 'frame__4__' | P6: 'horizontalLayout_1_' | Q6: '' | R6: 'horizontalLayout__4__' | S6: '' | T6: '市区町村: ' | U6: False | V6: True | W6: 0 | X6: '市区町村' | Y6: 0 | Z6: 0 | AA6: 0 | AB6: 0 | AC6: 0 | AD6: '' | AE6: 0
A7: 5 | B7: '町域番地:' | C7: 'str' | D7: 'label_5_' | E7: 'lineEdit_5_' | F7: 0 | G7: '' | H7: 'jp' | I7: 'town' | J7: 'han-ans' | K7: '' | L7: '' | M7: 'frame_1_' | N7: '' | O7: 'frame__5__' | P7: 'horizontalLayout_2_' | Q7: '' | R7: 'horizontalLayout__5__' | S7: '' | T7: '町域番地: ' | U7: False | V7: True | W7: 0 | X7: '町域番地' | Y7: 0 | Z7: 0 | AA7: 0 | AB7: 0 | AC7: 0 | AD7: '' | AE7: 0
A8: 6 | B8: '建物:' | C8: 'str' | D8: 'label_6_' | E8: 'lineEdit_6_' | F8: 0 | G8: '' | H8: 'jp' | I8: 'null' | J8: 'han-ans' | K8: '' | L8: '' | M8: 'frame_2_' | N8: '' | O8: 'frame__6__' | P8: 'horizontalLayout_2_' | Q8: '' | R8: 'horizontalLayout__6__' | S8: '' | T8: '建物: ' | U8: False | V8: True | W8: 0 | X8: '建物' | Y8: 0 | Z8: 0 | AA8: 0 | AB8: 0 | AC8: 0 | AD8: '' | AE8: 0
A9: 7 | B9: '氏名かな:' | C9: 'str' | D9: 'label_7_' | E9: 'lineEdit_7_' | F9: 0 | G9: '' | H9: 'jp' | I9: 'null' | J9: '' | K9: '' | L9: '' | M9: 'frame_2_' | N9: '' | O9: 'frame__7__' | P9: 'horizontalLayout_3_' | Q9: '' | R9: 'horizontalLayout__7__' | S9: '' | T9: '氏名かな: ひらがな スペースあり' | U9: False | V9: True | W9: 0 | X9: '氏名かな' | Y9: 0 | Z9: 0 | AA9: True | AB9: 0 | AC9: 0 | AD9: '' | AE9: 0
A10: 8 | B10: '氏名:' | C10: 'str' | D10: 'label_8_' | E10: 'lineEdit_8_' | F10: 0 | G10: '' | H10: 'jp' | I10: 'null' | J10: '' | K10: '' | L10: '' | M10: 'frame_2_' | N10: '' | O10: 'frame__8__' | P10: 'horizontalLayout_3_' | Q10: '' | R10: 'horizontalLayout__8__' | S10: '' | T10: '氏名: スペースあり' | U10: False | V10: True | W10: 0 | X10: '氏名' | Y10: 0 | Z10: 0 | AA10: 0 | AB10: 0 | AC10: 0 | AD10: '' | AE10: 0
A11: 9 | B11: '電話番号:' | C11: 'hankaku-eisu-kuromaru_lenrange' | D11: 'label_9_' | E11: 'lineEdit_9_' | F11: 0 | G11: '' | H11: 'en' | I11: 'null' | J11: 'han' | K11: '' | L11: '' | M11: 'frame_3_' | N11: '' | O11: 'frame__9__' | P11: 'horizontalLayout_3_' | Q11: '' | R11: 'horizontalLayout__9__' | S11: '' | T11: '電話番号: ハイフンなし 桁数:10～11' | U11: False | V11: True | W11: 0 | X11: '電話番号' | Y11: 0 | Z11: 0 | AA11: True | AB11: [10, 11] | AC11: 0 | AD11: '' | AE11: 0
A12: 10 | B12: '防災カルタ:' | C12: 'hankaku-eisu-kuromaru' | D12: 'label_10_' | E12: 'lineEdit_10_' | F12: 0 | G12: '' | H12: 'en' | I12: 'null' | J12: 'han' | K12: '' | L12: '' | M12: 'frame_3_' | N12: '' | O12: 'frame__10__' | P12: 'horizontalLayout_3_' | Q12: '' | R12: 'horizontalLayout__10__' | S12: '' | T12: '防災カルタ: 申し込む=1 不要=2' | U12: False | V12: True | W12: 0 | X12: '防災カルタ' | Y12: 0 | Z12: 0 | AA12: 0 | AB12: 0 | AC12: 0 | AD12: '' | AE12: 0
A13: 11 | B13: '404:薬剤式トイレ:' | C13: 'hankaku-eisu-kuromaru' | D13: 'label_11_' | E13: 'lineEdit_11_' | F13: 0 | G13: '' | H13: 'en' | I13: 'null' | J13: 'han' | K13: '' | L13: '' | M13: 'frame_3_' | N13: '' | O13: 'frame__11__' | P13: 'horizontalLayout_4_' | Q13: '' | R13: 'horizontalLayout__11__' | S13: '' | T13: '404:薬剤式トイレ: 数量を入力（薬剤式トイレ）' | U13: False | V13: True | W13: 0 | X13: '404:薬剤式トイレ' | Y13: 0 | Z13: 0 | AA13: True | AB13: 0 | AC13: 0 | AD13: '' | AE13: 0
A14: 12 | B14: '225:備蓄ランタン:' | C14: 'hankaku-eisu-kuromaru' | D14: 'label_12_' | E14: 'lineEdit_12_' | F14: 0 | G14: '' | H14: 'en' | I14: 'null' | J14: 'han' | K14: '' | L14: '' | M14: 'frame_4_' | N14: '' | O14: 'frame__12__' | P14: 'horizontalLayout_4_' | Q14: '' | R14: 'horizontalLayout__12__' | S14: '' | T14: '225:備蓄ランタン: 数量を入力（備蓄ランタン）' | U14: False | V14: True | W14: 0 | X14: '225:備蓄ランタン' | Y14: 0 | Z14: 0 | AA14: 0 | AB14: 0 | AC14: 0 | AD14: '' | AE14: 0
A15: 13 | B15: '512:彩り主食:' | C15: 'hankaku-eisu-kuromaru' | D15: 'label_13_' | E15: 'lineEdit_13_' | F15: 0 | G15: '' | H15: 'en' | I15: 'null' | J15: 'han' | K15: '' | L15: '' | M15: 'frame_4_' | N15: '' | O15: 'frame__13__' | P15: 'horizontalLayout_4_' | Q15: '' | R15: 'horizontalLayout__13__' | S15: '' | T15: '512:彩り主食: 数量を入力（彩り主食）' | U15: False | V15: True | W15: 0 | X15: '512:彩り主食' | Y15: 0 | Z15: 0 | AA15: 0 | AB15: 0 | AC15: 0 | AD15: '' | AE15: 0
A16: 14 | B16: '411&415:全身きれい:' | C16: 'hankaku-eisu-kuromaru' | D16: 'label_14_' | E16: 'lineEdit_14_' | F16: 1 | G16: '' | H16: 'en' | I16: 'null' | J16: 'han' | K16: '' | L16: '' | M16: 'frame_4_' | N16: '' | O16: 'frame__14__' | P16: 'horizontalLayout_4_' | Q16: '' | R16: 'horizontalLayout__14__' | S16: '' | T16: '411&415:全身きれい: 数量を入力（全身きれい・歯みがき）' | U16: False | V16: True | W16: 0 | X16: '411&415:全身きれい' | Y16: 0 | Z16: 0 | AA16: 0 | AB16: 0 | AC16: 0 | AD16: '' | AE16: 0

Sheet calcu2
A2: {=_xlfn.LET( _xlpm._col, COLUMN(), _xlpm._n, IF(_xlpm._col<=26, 1, 2), IFERROR(IF(INDIRECT("calcu1!"&ADDRESS(ROW(),COLUMN()))<>"", "'" & INDIRECT( "calcu1!" & LEFT(ADDRESS(ROW(), COLUMN(),4 ), _xlpm._n) & "$1" ) & "'" & ": " & INDIRECT("calcu1!"&ADDRESS(ROW(),COLUMN())), ""),"") )} -> 'index': 0 | B2: {=_xlfn.LET( _xlpm._col, COLUMN(), _xlpm._n, IF(_xlpm._col<=26, 1, 2), IFERROR(IF(INDIRECT("calcu1!"&ADDRESS(ROW(),COLUMN()))<>"", "'" & INDIRECT( "calcu1!" & LEFT(ADDRESS(ROW(), COLUMN(),4 ), _xlpm._n) & "$1" ) & "'" & ": " & INDIRECT("calcu1!"&ADDRESS(ROW(),COLUMN())), ""),"") )} -> 'display_name': 'ID:' | C2: {=_xlfn.LET( _xlpm._col, COLUMN(), _xlpm._n, IF(_xlpm._col<=26, 1, 2), IFERROR(IF(INDIRECT("calcu1!"&ADDRESS(ROW(),COLUMN()))<>"", "'" & INDIRECT( "calcu1!" & LEFT(ADDRESS(ROW(), COLUMN(),4 ), _xlpm._n) & "$1" ) & "'" & ": " & INDIRECT("calcu1!"&ADDRESS(ROW(),COLUMN())), ""),"") )} -> 'data_type': 'hankaku-eisu-kuromaru_lenjust' | D2: {=_xlfn.LET( _xlpm._col, COLUMN(), _xlpm._n, IF(_xlpm._col<=26, 1, 2), IFERROR(IF(INDIRECT("calcu1!"&ADDRESS(ROW(),COLUMN()))<>"", "'" & INDIRECT( "calcu1!" & LEFT(ADDRESS(ROW(), COLUMN(),4 ), _xlpm._n) & "$1" ) & "'" & ": " & INDIRECT("calcu1!"&ADDRESS(ROW(),COLUMN())), ""),"") )} -> 'label_name': 'label_0_' | E2: {=_xlfn.LET( _xlpm._col, COLUMN(), _xlpm._n, IF(_xlpm._col<=26, 1, 2), IFERROR(IF(INDIRECT("calcu1!"&ADDRESS(ROW(),COLUMN()))<>"", "'" & INDIRECT( "calcu1!" & LEFT(ADDRESS(ROW(), COLUMN(),4 ), _xlpm._n) & "$1" ) & "'" & ": " & INDIRECT("calcu1!"&ADDRESS(ROW(),COLUMN())), ""),"") )} -> 'line_edit_name': 'lineEdit_0_' | F2: {=_xlfn.LET( _xlpm._col, COLUMN(), _xlpm._n, IF(_xlpm._col<=26, 1, 2), IFERROR(IF(INDIRECT("calcu1!"&ADDRESS(ROW(),COLUMN()))<>"", "'" & INDIRECT( "calcu1!" & LEFT(ADDRESS(ROW(), COLUMN(),4 ), _xlpm._n) & "$1" ) & "'" & ": " & INDIRECT("calcu1!"&ADDRESS(ROW(),COLUMN())), ""),"") )} -> 'is_last': -1 | G2: {=_xlfn.LET( _xlpm._col, COLUMN(), _xlpm._n, IF(_xlpm._col<=26, 1, 2), IFERROR(IF(INDIRECT("calcu1!"&ADDRESS(ROW(),COLUMN()))<>"", "'" & INDIRECT( "calcu1!" & LEFT(ADDRESS(ROW(), COLUMN(),4 ), _xlpm._n) & "$1" ) & "'" & ": " & INDIRECT("calcu1!"&ADDRESS(ROW(),COLUMN())), ""),"") )} -> 'line_edit_obj': '' | H2: {=_xlfn.LET( _xlpm._col, COLUMN(), _xlpm._n, IF(_xlpm._col<=26, 1, 2), IFERROR(IF(INDIRECT("calcu1!"&ADDRESS(ROW(),COLUMN()))<>"", "'" & INDIRECT( "calcu1!" & LEFT(ADDRESS(ROW(), COLUMN(),4 ), _xlpm._n) & "$1" ) & "'" & ": " & INDIRECT("calcu1!"&ADDRESS(ROW(),COLUMN())), ""),"") )} -> 'ime_mode': 'en' | ... AE2: {=_xlfn.LET( _xlpm._col, COLUMN(), _xlpm._n, IF(_xlpm._col<=26, 1, 2), IFERROR(IF(INDIRECT("calcu1!"&ADDRESS(ROW(),COLUMN()))<>"", "'" & INDIRECT( "calcu1!" & LEFT(ADDRESS(ROW(), COLUMN(),4 ), _xlpm._n) & "$1" ) & "'" & ": " & INDIRECT("calcu1!"&ADDRESS(ROW(),COLUMN())), ""),"") )} -> 'remarks': 0
